Workbook

Sheet Cover
A5: Corporate valuation suite · Shell plc and BP p.l.c.
A6: Built 12 Oct 2026 by export_excel.py from the Python engine. Base case. Not investment advice.
A8: Model check status | B8: =Checks!F42 -> ALL PASS
A10: Contents
A11: Inputs | B11: Forecast and valuation assumptions for Shell (edit the blue cells)
A12: Forecast | B12: Integrated income statement, cash flow and balance sheet, 2026–2035
A13: DCF | B13: WACC, unlevered free cash flow, terminal value, equity bridge, sensitivity grid
A14: LBO | B14: Carve-out buyout of Shell's Marketing division: sources and uses, debt schedule, returns
A15: Merger | B15: Shell acquires BP: consideration, funding, purchase price allocation, EPS accretion
A16: Portfolio | B16: 13-asset sterling portfolio: expected returns, covariance, portfolio statistics
A17: Checks | B17: Every key result reconciled to the Python engine
A18: History | B18: Shell FY2021–FY2025 reported figures from the 20-F
A20: Colour code
A21: Blue text: hard-coded input
A22: Black text: formula
A23: Green text: link to another sheet
A24: Yellow fill: key assumption
A26: Calculation
A27: Interest on average balances makes the Forecast and LBO sheets circular. Iterative calculation is saved with the workbook; if Excel warns about circular references, enable File › Options › Formulas › Enable iterative calculation.

Sheet Inputs
A1: Shell plc · forecast and valuation inputs
A2: Base case. Blue cells are inputs; change them and every sheet recalculates. Defaults are calibrated from Shell's own history by the Python engine (model/three_statement.py).
A4: Annual drivers | B4: Unit | C4: 2026 | D4: 2027 | E4: 2028 | F4: 2029 | G4: 2030 | H4: 2031 | I4: 2032 | J4: 2033 | K4: 2034 | L4: 2035
A5: Revenue growth | B5: % | C5: -0.01 | D5: 0.01 | E5: 0.02 | F5: 0.02 | G5: 0.02 | H5: 0.019 | I5: 0.018 | J5: 0.017 | K5: 0.016 | L5: 0.015
A6: Operating EBIT margin | B6: % | C6: 0.10938983 | D6: 0.10938983 | E6: 0.10938983 | F6: 0.10938983 | G6: 0.10938983 | H6: 0.10938983 | I6: 0.10938983 | J6: 0.10938983 | K6: 0.10938983 | L6: 0.10938983
A7: D&A excl. impairments | B7: % rev | C7: 0.083054188 | D7: 0.083054188 | E7: 0.083054188 | F7: 0.083054188 | G7: 0.083054188 | H7: 0.083054188 | I7: 0.083054188 | J7: 0.083054188 | K7: 0.083054188 | L7: 0.083054188
A8: Capital expenditure | B8: % rev | C8: 0.070992858 | D8: 0.070992858 | E8: 0.070992858 | F8: 0.070992858 | G8: 0.070992858 | H8: 0.070992858 | I8: 0.070992858 | J8: 0.070992858 | K8: 0.070992858 | L8: 0.070992858
A9: New leases = lease principal repaid | B9: % rev | C9: 0.019712536 | D9: 0.019712536 | E9: 0.019712536 | F9: 0.019712536 | G9: 0.019712536 | H9: 0.019712536 | I9: 0.019712536 | J9: 0.019712536 | K9: 0.019712536 | L9: 0.019712536
A10: Tax rate on pre-tax profit ex JV | B10: % | C10: 0.38444881 | D10: 0.38167103 | E10: 0.37889325 | F10: 0.37611548 | G10: 0.3733377 | H10: 0.37055992 | I10: 0.36778214 | J10: 0.36500436 | K10: 0.36222659 | L10: 0.35944881
A11: Share of JV profit | B11: % rev | C11: 0.0094515242 | D11: 0.0094515242 | E11: 0.0094515242 | F11: 0.0094515242 | G11: 0.0094515242 | H11: 0.0094515242 | I11: 0.0094515242 | J11: 0.0094515242 | K11: 0.0094515242 | L11: 0.0094515242
A12: Dividends | B12: USD m | C12: 8963.76 | D12: 9322.3104 | E12: 9695.2028 | F12: 10083.011 | G12: 10486.331 | H12: 10748.49 | I12: 11017.202 | J12: 11292.632 | K12: 11574.948 | L12: 11864.321
A13: Buyback target (flexes to protect cash floor) | B13: USD m | C13: 13879 | D13: 13879 | E13: 13879 | F13: 13879 | G13: 13879 | H13: 13879 | I13: 13879 | J13: 13879 | K13: 13879 | L13: 13879
A14: Net new borrowing | B14: USD m | C14: 0 | D14: 0 | E14: 0 | F14: 0 | G14: 0 | H14: 0 | I14: 0 | J14: 0 | K14: 0 | L14: 0
A16: Balance-sheet and financing drivers
A17: Receivables | B17: % rev | C17: 0.16710131
A18: Inventories | B18: % rev | C18: 0.083241534
A19: Payables | B19: % rev | C19: 0.21645946
A20: Interest rate on borrowings + leases | B20: % | C20: 0.04466608
A21: Interest rate on cash | B21: % | C21: 0.03
A22: Minority (NCI) income, fixed | B22: USD m | C22: 328.66667
A23: Minimum cash | B23: % rev | C23: 0.09
A24: Circularity switch: 1 = interest on average balances, 0 = opening balances | B24: 1/0 | C24: 1
A26: Valuation inputs
A27: Risk-free rate (US 10y, blend of spot and 1-year average) | B27: % | C27: 0.048206906
A28: Equity risk premium | B28: % | C28: 0.05
A29: Beta (5y weekly vs FTSE 100, Blume-adjusted) | B29: x | C29: 0.972
A30: Credit spread over risk-free | B30: % | C30: 0.009
A31: Tax rate on interest / provisions | B31: % | C31: 0.25
A32: Terminal growth | B32: % | C32: 0.015
A33: Exit EV/EBITDA (cross-check) | B33: x | C33: 5
A34: Shares outstanding | B34: m | C34: 5691.4747
A35: Share price | B35: GBp | C35: 3836
A36: GBP/USD | B36: USD per GBP | C36: 1.3207946
A37: Valuation date | B37: date | C37: 46305

Sheet Forecast
A1: Shell plc · integrated three-statement forecast
A2: USD millions. Column B is the FY2025 opening balance sheet (from History); C–L are forecasts. Interest is on average balances, so the sheet is circular: iterative calculation is switched on.
B4: 2025A | C4: 2026E | D4: 2027E | E4: 2028E | F4: 2029E | G4: 2030E | H4: 2031E | I4: 2032E | J4: 2033E | K4: 2034E | L4: 2035E
A5: Income statement
A6: Revenue | B6: =History!$F$5 -> 266886 | C6: =B6*(1+Inputs!C$5) -> 264217.14 | D6: =C6*(1+Inputs!D$5) -> 266859.31 | E6: =D6*(1+Inputs!E$5) -> 272196.5 | F6: =E6*(1+Inputs!F$5) -> 277640.43 | G6: =F6*(1+Inputs!G$5) -> 283193.24 | H6: =G6*(1+Inputs!H$5) -> 288573.91 | I6: =H6*(1+Inputs!I$5) -> 293768.24 | J6: =I6*(1+Inputs!J$5) -> 298762.3 | ... L6: =K6*(1+Inputs!L$5) -> 308095.63
A7: Operating EBIT | C7: =C6*Inputs!C$6 -> 28902.669 | D7: =D6*Inputs!D$6 -> 29191.695 | E7: =E6*Inputs!E$6 -> 29775.529 | F7: =F6*Inputs!F$6 -> 30371.04 | G7: =G6*Inputs!G$6 -> 30978.461 | H7: =H6*Inputs!H$6 -> 31567.051 | I7: =I6*Inputs!I$6 -> 32135.258 | J7: =J6*Inputs!J$6 -> 32681.558 | ... L7: =L6*Inputs!L$6 -> 33702.53
A8: D&A | C8: =C6*Inputs!C$7 -> 21944.34 | D8: =D6*Inputs!D$7 -> 22163.783 | E8: =E6*Inputs!E$7 -> 22607.059 | F8: =F6*Inputs!F$7 -> 23059.2 | G8: =G6*Inputs!G$7 -> 23520.384 | H8: =H6*Inputs!H$7 -> 23967.272 | I8: =I6*Inputs!I$7 -> 24398.682 | J8: =J6*Inputs!J$7 -> 24813.46 | ... L8: =L6*Inputs!L$7 -> 25588.633
A9: EBITDA | C9: =C7+C8 -> 50847.009 | D9: =D7+D8 -> 51355.479 | E9: =E7+E8 -> 52382.588 | F9: =F7+F8 -> 53430.24 | G9: =G7+G8 -> 54498.845 | H9: =H7+H8 -> 55534.323 | I9: =I7+I8 -> 56533.941 | J9: =J7+J8 -> 57495.018 | ... L9: =L7+L8 -> 59291.162
A10: Interest expense | C10: =IFERROR(Inputs!$C$20*(IF(Inputs!$C$24=1,((B46+B47)+(B46+B47+Inputs!C$14+C33-C34))/2,(B46+B47))+B48),0) -> 4671 | D10: =IFERROR(Inputs!$C$20*(IF(Inputs!$C$24=1,((C46+C47)+(C46+C47+Inputs!D$14+D33-D34))/2,(C46+C47))+C48),0) -> 4671 | E10: =IFERROR(Inputs!$C$20*(IF(Inputs!$C$24=1,((D46+D47)+(D46+D47+Inputs!E$14+E33-E34))/2,(D46+D47))+D48),0) -> 4671 | F10: =IFERROR(Inputs!$C$20*(IF(Inputs!$C$24=1,((E46+E47)+(E46+E47+Inputs!F$14+F33-F34))/2,(E46+E47))+E48),0) -> 4671 | G10: =IFERROR(Inputs!$C$20*(IF(Inputs!$C$24=1,((F46+F47)+(F46+F47+Inputs!G$14+G33-G34))/2,(F46+F47))+F48),0) -> 4671 | H10: =IFERROR(Inputs!$C$20*(IF(Inputs!$C$24=1,((G46+G47)+(G46+G47+Inputs!H$14+H33-H34))/2,(G46+G47))+G48),0) -> 4671 | I10: =IFERROR(Inputs!$C$20*(IF(Inputs!$C$24=1,((H46+H47)+(H46+H47+Inputs!I$14+I33-I34))/2,(H46+H47))+H48),0) -> 4671 | J10: =IFERROR(Inputs!$C$20*(IF(Inputs!$C$24=1,((I46+I47)+(I46+I47+Inputs!J$14+J33-J34))/2,(I46+I47))+I48),0) -> 4671 | ... L10: =IFERROR(Inputs!$C$20*(IF(Inputs!$C$24=1,((K46+K47)+(K46+K47+Inputs!L$14+L33-L34))/2,(K46+K47))+K48),0) -> 4671
A11: Interest income | C11: =IFERROR(Inputs!$C$21*IF(Inputs!$C$24=1,(B41+C41)/2,B41),0) -> 809.93314 | D11: =IFERROR(Inputs!$C$21*IF(Inputs!$C$24=1,(C41+D41)/2,C41),0) -> 716.95321 | E11: =IFERROR(Inputs!$C$21*IF(Inputs!$C$24=1,(D41+E41)/2,D41),0) -> 727.72534 | F11: =IFERROR(Inputs!$C$21*IF(Inputs!$C$24=1,(E41+F41)/2,E41),0) -> 742.27985 | G11: =IFERROR(Inputs!$C$21*IF(Inputs!$C$24=1,(F41+G41)/2,F41),0) -> 757.12545 | H11: =IFERROR(Inputs!$C$21*IF(Inputs!$C$24=1,(G41+H41)/2,G41),0) -> 771.88564 | I11: =IFERROR(Inputs!$C$21*IF(Inputs!$C$24=1,(H41+I41)/2,H41),0) -> 786.1619 | J11: =IFERROR(Inputs!$C$21*IF(Inputs!$C$24=1,(I41+J41)/2,I41),0) -> 799.91622 | ... L11: =IFERROR(Inputs!$C$21*IF(Inputs!$C$24=1,(K41+L41)/2,K41),0) -> 825.71147
A12: Pre-tax profit ex JV | C12: =C7-C10+C11 -> 25041.602 | D12: =D7-D10+D11 -> 25237.649 | E12: =E7-E10+E11 -> 25832.255 | F12: =F7-F10+F11 -> 26442.32 | G12: =G7-G10+G11 -> 27064.586 | H12: =H7-H10+H11 -> 27667.937 | I12: =I7-I10+I11 -> 28250.42 | J12: =J7-J10+J11 -> 28810.474 | ... L12: =L7-L10+L11 -> 29857.241
A13: Tax | C13: =C12*Inputs!C$10 -> 9627.214 | D13: =D12*Inputs!D$10 -> 9632.4794 | E13: =E12*Inputs!E$10 -> 9787.667 | F13: =F12*Inputs!F$10 -> 9945.3657 | G13: =G12*Inputs!G$10 -> 10104.23 | H13: =H12*Inputs!H$10 -> 10252.629 | I13: =I12*Inputs!I$10 -> 10390 | J13: =J12*Inputs!J$10 -> 10515.949 | ... L13: =L12*Inputs!L$10 -> 10732.15
A14: Share of JV profit | C14: =C6*Inputs!C$11 -> 2497.2547 | D14: =D6*Inputs!D$11 -> 2522.2272 | E14: =E6*Inputs!E$11 -> 2572.6718 | F14: =F6*Inputs!F$11 -> 2624.1252 | G14: =G6*Inputs!G$11 -> 2676.6077 | H14: =H6*Inputs!H$11 -> 2727.4633 | I14: =I6*Inputs!I$11 -> 2776.5576 | J14: =J6*Inputs!J$11 -> 2823.7591 | ... L14: =L6*Inputs!L$11 -> 2911.9733
A15: Net income | C15: =C12-C13+C14 -> 17911.643 | D15: =D12-D13+D14 -> 18127.397 | E15: =E12-E13+E14 -> 18617.259 | F15: =F12-F13+F14 -> 19121.079 | G15: =G12-G13+G14 -> 19636.964 | H15: =H12-H13+H14 -> 20142.772 | I15: =I12-I13+I14 -> 20636.978 | J15: =J12-J13+J14 -> 21118.284 | ... L15: =L12-L13+L14 -> 22037.065
A16: Minorities | C16: =Inputs!$C$22 -> 328.66667 | D16: =Inputs!$C$22 -> 328.66667 | E16: =Inputs!$C$22 -> 328.66667 | F16: =Inputs!$C$22 -> 328.66667 | G16: =Inputs!$C$22 -> 328.66667 | H16: =Inputs!$C$22 -> 328.66667 | I16: =Inputs!$C$22 -> 328.66667 | J16: =Inputs!$C$22 -> 328.66667 | ... L16: =Inputs!$C$22 -> 328.66667
A17: Net income to shareholders | C17: =C15-C16 -> 17582.976 | D17: =D15-D16 -> 17798.73 | E17: =E15-E16 -> 18288.593 | F17: =F15-F16 -> 18792.413 | G17: =G15-G16 -> 19308.297 | H17: =H15-H16 -> 19814.105 | I17: =I15-I16 -> 20308.311 | J17: =J15-J16 -> 20789.618 | ... L17: =L15-L16 -> 21708.398
A19: Working capital
A20: Receivables | B20: =History!$F$22 -> 44597 | C20: =C6*Inputs!$C$17 -> 44151.03 | D20: =D6*Inputs!$C$17 -> 44592.54 | E20: =E6*Inputs!$C$17 -> 45484.391 | F20: =F6*Inputs!$C$17 -> 46394.079 | G20: =G6*Inputs!$C$17 -> 47321.961 | H20: =H6*Inputs!$C$17 -> 48221.078 | I20: =I6*Inputs!$C$17 -> 49089.057 | J20: =J6*Inputs!$C$17 -> 49923.571 | ... L20: =L6*Inputs!$C$17 -> 51483.183
A21: Inventories | B21: =History!$F$21 -> 22216 | C21: =C6*Inputs!$C$18 -> 21993.84 | D21: =D6*Inputs!$C$18 -> 22213.778 | E21: =E6*Inputs!$C$18 -> 22658.054 | F21: =F6*Inputs!$C$18 -> 23111.215 | G21: =G6*Inputs!$C$18 -> 23573.439 | H21: =H6*Inputs!$C$18 -> 24021.335 | I21: =I6*Inputs!$C$18 -> 24453.719 | J21: =J6*Inputs!$C$18 -> 24869.432 | ... L21: =L6*Inputs!$C$18 -> 25646.353
A22: Payables | B22: =History!$F$28 -> 57770 | C22: =C6*Inputs!$C$19 -> 57192.3 | D22: =D6*Inputs!$C$19 -> 57764.223 | E22: =E6*Inputs!$C$19 -> 58919.507 | F22: =F6*Inputs!$C$19 -> 60097.898 | G22: =G6*Inputs!$C$19 -> 61299.856 | H22: =H6*Inputs!$C$19 -> 62464.553 | I22: =I6*Inputs!$C$19 -> 63588.915 | J22: =J6*Inputs!$C$19 -> 64669.926 | ... L22: =L6*Inputs!$C$19 -> 66690.215
A23: Increase in working capital | C23: =(C20-B20)+(C21-B21)-(C22-B22) -> -90.43 | D23: =(D20-C20)+(D21-C21)-(D22-C22) -> 89.5257 | E23: =(E20-D20)+(E21-D21)-(E22-D22) -> 180.84191 | F23: =(F20-E20)+(F21-E21)-(F22-E22) -> 184.45875 | G23: =(G20-F20)+(G21-F21)-(G22-F22) -> 188.14793 | H23: =(H20-G20)+(H21-G21)-(H22-G22) -> 182.31534 | I23: =(I20-H20)+(I21-H21)-(I22-H22) -> 176.00147 | J23: =(J20-I20)+(J21-I21)-(J22-I22) -> 169.21564 | ... L23: =(L20-K20)+(L21-K21)-(L22-K22) -> 154.27569
A24: Minimum cash (floor) | C24: =C6*Inputs!$C$23 -> 23779.543 | D24: =D6*Inputs!$C$23 -> 24017.338 | E24: =E6*Inputs!$C$23 -> 24497.685 | F24: =F6*Inputs!$C$23 -> 24987.638 | G24: =G6*Inputs!$C$23 -> 25487.391 | H24: =H6*Inputs!$C$23 -> 25971.652 | I24: =I6*Inputs!$C$23 -> 26439.141 | J24: =J6*Inputs!$C$23 -> 26888.607 | ... L24: =L6*Inputs!$C$23 -> 27728.607
A26: Cash flow
A27: Cash from operations | C27: =C15+C8-C23 -> 39946.413 | D27: =D15+D8-D23 -> 40201.654 | E27: =E15+E8-E23 -> 41043.477 | F27: =F15+F8-F23 -> 41995.821 | G27: =G15+G8-G23 -> 42969.2 | H27: =H15+H8-H23 -> 43927.728 | I27: =I15+I8-I23 -> 44859.659 | J27: =J15+J8-J23 -> 45762.529 | ... L27: =L15+L8-L23 -> 47471.422
A28: Capital expenditure | C28: =C6*Inputs!C$8 -> 18757.53 | D28: =D6*Inputs!D$8 -> 18945.105 | E28: =E6*Inputs!E$8 -> 19324.007 | F28: =F6*Inputs!F$8 -> 19710.488 | G28: =G6*Inputs!G$8 -> 20104.697 | H28: =H6*Inputs!H$8 -> 20486.687 | I28: =I6*Inputs!I$8 -> 20855.447 | J28: =J6*Inputs!J$8 -> 21209.99 | ... L28: =L6*Inputs!L$8 -> 21872.59
A29: Lease principal / new leases | C29: =C6*Inputs!C$9 -> 5208.39 | D29: =D6*Inputs!D$9 -> 5260.4739 | E29: =E6*Inputs!E$9 -> 5365.6834 | F29: =F6*Inputs!F$9 -> 5472.997 | G29: =G6*Inputs!G$9 -> 5582.457 | H29: =H6*Inputs!H$9 -> 5688.5237 | I29: =I6*Inputs!I$9 -> 5790.9171 | J29: =J6*Inputs!J$9 -> 5889.3627 | ... L29: =L6*Inputs!L$9 -> 6073.3464
A30: Cash from investing | C30: =-C28 -> -18757.53 | D30: =-D28 -> -18945.105 | E30: =-E28 -> -19324.007 | F30: =-F28 -> -19710.488 | G30: =-G28 -> -20104.697 | H30: =-H28 -> -20486.687 | I30: =-I28 -> -20855.447 | J30: =-J28 -> -21209.99 | ... L30: =-L28 -> -21872.59
A31: Cash before buybacks and revolver | C31: =B41+C27+C30+Inputs!C$14-C36-C16-C29 -> 36904.066 | D31: =C41+D27+D30+Inputs!D$14-D36-D16-D29 -> 30124.641 | E31: =D41+E27+E30+Inputs!E$14-E36-E16-E29 -> 30347.254 | F31: =E41+F27+F30+Inputs!F$14-F36-F16-F29 -> 30898.343 | G31: =F41+G27+G30+Inputs!G$14-G36-G16-G29 -> 31454.686 | H31: =G41+H27+H30+Inputs!H$14-H36-H16-H29 -> 32162.753 | I31: =H41+I27+I30+Inputs!I$14-I36-I16-I29 -> 32839.078 | J31: =I41+J27+J30+Inputs!J$14-J36-J16-J29 -> 33481.019 | ... L31: =K41+L27+L30+Inputs!L$14-L36-L16-L29 -> 34651.322
A32: Cash available above the floor | C32: =C31-C24 -> 13124.523 | D32: =D31-D24 -> 6107.3025 | E32: =E31-E24 -> 5849.5696 | F32: =F31-F24 -> 5910.7049 | G32: =G31-G24 -> 5967.2948 | H32: =H31-H24 -> 6191.1011 | I32: =I31-I24 -> 6399.9365 | J32: =J31-J24 -> 6592.4126 | ... L32: =L31-L24 -> 6922.7151
A33: Revolver drawn | C33: =MAX(0,-C32) -> 0 | D33: =MAX(0,-D32) -> 0 | E33: =MAX(0,-E32) -> 0 | F33: =MAX(0,-F32) -> 0 | G33: =MAX(0,-G32) -> 0 | H33: =MAX(0,-H32) -> 0 | I33: =MAX(0,-I32) -> 0 | J33: =MAX(0,-J32) -> 0 | ... L33: =MAX(0,-L32) -> 0
A34: Revolver repaid | C34: =MIN(B47,MAX(0,C32)) -> 0 | D34: =MIN(C47,MAX(0,D32)) -> 0 | E34: =MIN(D47,MAX(0,E32)) -> 0 | F34: =MIN(E47,MAX(0,F32)) -> 0 | G34: =MIN(F47,MAX(0,G32)) -> 0 | H34: =MIN(G47,MAX(0,H32)) -> 0 | I34: =MIN(H47,MAX(0,I32)) -> 0 | J34: =MIN(I47,MAX(0,J32)) -> 0 | ... L34: =MIN(K47,MAX(0,L32)) -> 0
A35: Share buybacks | C35: =MAX(0,MIN(Inputs!C$13,C32-C34)) -> 13124.523 | D35: =MAX(0,MIN(Inputs!D$13,D32-D34)) -> 6107.3025 | E35: =MAX(0,MIN(Inputs!E$13,E32-E34)) -> 5849.5696 | F35: =MAX(0,MIN(Inputs!F$13,F32-F34)) -> 5910.7049 | G35: =MAX(0,MIN(Inputs!G$13,G32-G34)) -> 5967.2948 | H35: =MAX(0,MIN(Inputs!H$13,H32-H34)) -> 6191.1011 | I35: =MAX(0,MIN(Inputs!I$13,I32-I34)) -> 6399.9365 | J35: =MAX(0,MIN(Inputs!J$13,J32-J34)) -> 6592.4126 | ... L35: =MAX(0,MIN(Inputs!L$13,L32-L34)) -> 6922.7151
A36: Dividends | C36: =Inputs!C$12 -> 8963.76 | D36: =Inputs!D$12 -> 9322.3104 | E36: =Inputs!E$12 -> 9695.2028 | F36: =Inputs!F$12 -> 10083.011 | G36: =Inputs!G$12 -> 10486.331 | H36: =Inputs!H$12 -> 10748.49 | I36: =Inputs!I$12 -> 11017.202 | J36: =Inputs!J$12 -> 11292.632 | ... L36: =Inputs!L$12 -> 11864.321
A37: Cash from financing | C37: =Inputs!C$14+C33-C34-C36-C35-C16-C29 -> -27625.34 | D37: =Inputs!D$14+D33-D34-D36-D35-D16-D29 -> -21018.753 | E37: =Inputs!E$14+E33-E34-E36-E35-E16-E29 -> -21239.122 | F37: =Inputs!F$14+F33-F34-F36-F35-F16-F29 -> -21795.38 | G37: =Inputs!G$14+G33-G34-G36-G35-G16-G29 -> -22364.75 | H37: =Inputs!H$14+H33-H34-H36-H35-H16-H29 -> -22956.781 | I37: =Inputs!I$14+I33-I34-I36-I35-I16-I29 -> -23536.722 | J37: =Inputs!J$14+J33-J34-J36-J35-J16-J29 -> -24103.074 | ... L37: =Inputs!L$14+L33-L34-L36-L35-L16-L29 -> -25189.05
A38: Net change in cash | C38: =C27+C30+C37 -> -6436.4574 | D38: =D27+D30+D37 -> 237.79543 | E38: =E27+E30+E37 -> 480.34676 | F38: =F27+F30+F37 -> 489.9537 | G38: =G27+G30+G37 -> 499.75277 | H38: =H27+H30+H37 -> 484.26043 | I38: =I27+I30+I37 -> 467.48973 | J38: =J27+J30+J37 -> 449.4654 | ... L38: =L27+L30+L37 -> 409.78237
A40: Balance sheet
A41: Cash | B41: =History!$F$20 -> 30216 | C41: =B41+C38 -> 23779.543 | D41: =C41+D38 -> 24017.338 | E41: =D41+E38 -> 24497.685 | F41: =E41+F38 -> 24987.638 | G41: =F41+G38 -> 25487.391 | H41: =G41+H38 -> 25971.652 | I41: =H41+I38 -> 26439.141 | J41: =I41+J38 -> 26888.607 | ... L41: =K41+L38 -> 27728.607
A42: Fixed assets incl. right-of-use | B42: =History!$F$23+History!$F$25 -> 196087 | C42: =B42+C28+C29-C8 -> 198108.58 | D42: =C42+D28+D29-D8 -> 200150.38 | E42: =D42+E28+E29-E8 -> 202233.01 | F42: =E42+F28+F29-F8 -> 204357.29 | G42: =F42+G28+G29-G8 -> 206524.06 | H42: =G42+H28+H29-H8 -> 208732 | I42: =H42+I28+I29-I8 -> 210979.68 | J42: =I42+J28+J29-J8 -> 213265.57 | ... L42: =K42+L28+L29-L8 -> 217945.34
A43: Goodwill | B43: =History!$F$24 -> 15662 | C43: =B43 -> 15662 | D43: =C43 -> 15662 | E43: =D43 -> 15662 | F43: =E43 -> 15662 | G43: =F43 -> 15662 | H43: =G43 -> 15662 | I43: =H43 -> 15662 | J43: =I43 -> 15662 | ... L43: =K43 -> 15662
A44: Other assets (plug, held flat) | B44: =History!$F$18-B41-B20-B21-B42-B43 -> 61572 | C44: =B44 -> 61572 | D44: =C44 -> 61572 | E44: =D44 -> 61572 | F44: =E44 -> 61572 | G44: =F44 -> 61572 | H44: =G44 -> 61572 | I44: =H44 -> 61572 | J44: =I44 -> 61572 | ... L44: =K44 -> 61572
...

Sheet DCF
A1: Shell plc · discounted cash flow
A2: USD millions unless stated. Mid-year discounting from 31 Dec 2025; value rolled forward to the valuation date.
A4: Cost of capital
A5: Cost of equity = risk-free + beta × ERP | B5: =Inputs!$C$27+Inputs!$C$29*Inputs!$C$28 -> 0.096806906
A6: After-tax cost of debt = (risk-free + spread) × (1 − tax) | B6: =(Inputs!$C$27+Inputs!$C$30)*(1-Inputs!$C$31) -> 0.042905179
A7: Market capitalisation (USD m) | B7: =Inputs!$C$34*Inputs!$C$35/100*Inputs!$C$36 -> 288362.44
A8: Borrowings + leases at book (USD m) | B8: =History!$F$29+History!$F$30+History!$F$31 -> 104576
A9: WACC | B9: =(B7*B5+B8*B6)/(B7+B8) -> 0.082461588
A11: Cash flows
C12: 2026E | D12: 2027E | E12: 2028E | F12: 2029E | G12: 2030E | H12: 2031E | I12: 2032E | J12: 2033E | K12: 2034E | L12: 2035E
A13: Unlevered free cash flow | C13: =Forecast!C57 -> 15859.922 | D13: =Forecast!D57 -> 15918.749 | E13: =Forecast!E57 -> 16230.309 | F13: =Forecast!F57 -> 16639.279 | G13: =Forecast!G57 -> 17058.116 | H13: =Forecast!H57 -> 17479.313 | I13: =Forecast!I57 -> 17892.801 | J13: =Forecast!J57 -> 18297.539 | ... L13: =Forecast!L57 -> 19076.616
A14: Discount period (years, mid-year) | C14: 0.5 | D14: 1.5 | E14: 2.5 | F14: 3.5 | G14: 4.5 | H14: 5.5 | I14: 6.5 | J14: 7.5 | K14: 8.5 | L14: 9.5
A15: Discount factor | C15: =1/(1+$B$9)^C14 -> 0.96115572 | D15: =1/(1+$B$9)^D14 -> 0.88793517 | E15: =1/(1+$B$9)^E14 -> 0.82029255 | F15: =1/(1+$B$9)^F14 -> 0.75780291 | G15: =1/(1+$B$9)^G14 -> 0.70007372 | H15: =1/(1+$B$9)^H14 -> 0.64674233 | I15: =1/(1+$B$9)^I14 -> 0.5974737 | J15: =1/(1+$B$9)^J14 -> 0.55195833 | ... L15: =1/(1+$B$9)^L14 -> 0.47106551
A16: Present value | C16: =C13*C15 -> 15243.855 | D16: =D13*D15 -> 14134.818 | E16: =E13*E15 -> 13313.601 | F16: =F13*F15 -> 12609.294 | G16: =G13*G15 -> 11941.938 | H16: =H13*H15 -> 11304.612 | I16: =I13*I15 -> 10690.478 | J16: =J13*J15 -> 10099.479 | ... L16: =L13*L15 -> 8986.336
A18: Enterprise value to equity value
A19: PV of 10-year cash flows | B19: =SUM(C16:L16) -> 117855.9
A20: Terminal value (Gordon) at 2035 | B20: =L13*(1+Inputs!$C$32)/($B$9-Inputs!$C$32) -> 287019.12
A21: PV of terminal value | B21: =B20/(1+$B$9)^(L14) -> 135204.81
A22: Enterprise value | B22: =B19+B21 -> 253060.71
A23: + Equity-accounted JV stakes (book) | B23: =History!$F$38 -> 27775
A24: − Borrowings | B24: =-(History!$F$29+History!$F$30) -> -75643
A25: − Lease liabilities | B25: =-History!$F$31 -> -28933
A26: + Cash | B26: =History!$F$20 -> 30216
A27: − Minorities | B27: =-History!$F$34 -> -927
A28: − Decommissioning provisions, after tax | B28: =-History!$F$42*(1-Inputs!$C$31) -> -14100.75
A29: − Pension deficit, after tax | B29: =-History!$F$43*(1-Inputs!$C$31) -> -1563
A30: Equity value at 31 Dec 2025 | B30: =SUM(B22:B29) -> 189884.96
A31: Roll-forward (years from 31 Dec 2025) | B31: =(Inputs!$C$37-DATE(2025,12,31))/365 -> 0.77534247
A32: Dividend per share paid in the interim (USD) | B32: =Inputs!C$12/Inputs!$C$34 -> 1.5749451
A33: Value per share (USD) | B33: =B30/Inputs!$C$34*(1+B5)^B31-B32*B31 -> 34.619901
A34: Value per share (pence) | B34: =B33/Inputs!$C$36*100 -> 2621.1419
A35: Upside to market price | B35: =B34/Inputs!$C$35-1 -> -0.31669918
A36: Terminal value share of EV | B36: =B21/B22 -> 0.53427815
A37: Implied exit EV/EBITDA | B37: =B20/Forecast!L9 -> 4.8408416
A39: Cross-check: exit multiple
A40: Terminal value = exit multiple × 2035 EBITDA | B40: =Inputs!$C$33*Forecast!L9 -> 296455.81
A41: PV of terminal value (end-year) | B41: =B40/(1+$B$9)^10 -> 134225.5
A42: Equity value | B42: =B19+B41+SUM(B23:B29) -> 188905.65
A43: Value per share (pence) | B43: =(B42/Inputs!$C$34*(1+B5)^B31-B32*B31)/Inputs!$C$36*100 -> 2607.1469
A45: Sensitivity: value per share (pence), WACC down the side, terminal growth across
...

Sheet LBO
A1: Carve-out LBO · Shell Marketing division
A2: USD millions. Division financials from Shell's FY2025 Form 20-F, note 7 (segment information). Sweep, revolver and interest on average balances are circular: iterative calculation is on.
A4: Operating base
A5: LTM revenue incl. inter-segment | B5: 119394
A6: LTM EBITDA (reported basis) | B6: 7902
A7: D&A excl. impairments, % revenue | B7: 0.019280701
A8: Capex, % revenue | B8: 0.015419535
A9: Working capital, % revenue (group proxy) | B9: 0.033883381
A10: Standalone costs, % revenue | B10: 0.004
A11: Tax rate | B11: 0.28
A12: Interest deductibility cap, % EBITDA | B12: 0.3
A13: Deal
A14: Entry EV / LTM EBITDA | B14: 7.5
A15: Exit EV / EBITDA | B15: 7.5
A16: Hold period (years) | B16: 5
A17: Advisory fees, % EV | B17: 0.01
A18: Separation costs, % EV | B18: 0.01
A19: Exit costs, % exit EV | B19: 0.01
A20: Minimum cash, % revenue | B20: 0.01
A21: Management promote, % of gain | B21: 0
A22: Financing
A23: Term loan B, x pro-forma EBITDA | B23: 3
A24: Senior notes, x | B24: 1.5
A25: Mezzanine, x | B25: 0.5
A26: Maximum debt, % of EV | B26: 0.7
A27: Base rate (US 13-week T-bill) | B27: 0.040500002
A28: TLB spread | B28: 0.035
A29: Notes coupon | B29: 0.075
A30: Mezzanine cash coupon | B30: 0.08
A31: Mezzanine PIK coupon | B31: 0.03
A32: Revolver commitment, x | B32: 0.75
A33: Revolver spread | B33: 0.03
A34: Undrawn fee | B34: 0.005
... A39: Circularity switch: 1 = average balances, 0 = opening | B39: 1
A41: Sources and uses
A42: Purchase price (EV) | B42: =$B$14*$B$6 -> 59265
A43: Pro-forma EBITDA (after standalone costs) | B43: =$B$6-$B$5*$B$10 -> 7424.424
A44: Debt scale factor (LTV cap) | B44: =MIN(1,$B$26*B42/(($B$23+$B$24+$B$25)*B43)) -> 1
A45: Term loan B | B45: =$B$23*B43*B44 -> 22273.272
A46: Senior notes | B46: =$B$24*B43*B44 -> 11136.636
...

Sheet Merger
A1: Shell acquires BP · deal terms, purchase accounting and EPS
A2: USD millions. Terms and accounting are live formulas. Standalone and pro forma net income come from the Python engine (the full pro forma forecast is in model/ma.py) and are marked as such.
A4: Market data
A5: Shell share price (GBp) | B5: 3836
A6: Shell shares (m) | B6: 5691.4747
A7: BP share price (GBp) | B7: 588
A8: BP shares (m) | B8: 15453.549
A9: GBP/USD | B9: 1.3207946
A10: Terms
A11: Premium to BP share price | B11: 0.3
A12: Paid in Shell shares | B12: 0.5
A13: Advisory fees, % target EV | B13: 0.003
A14: Financing fees, % acquisition debt | B14: 0.01
A15: Cash consideration funded from cash (USD m) | B15: 0
A16: BP divested, % of EBITDA | B16: 0
A17: Divestment EV/EBITDA | B17: 6
A18: Fair-value uplift on BP fixed assets | B18: 0.08
A19: Deferred tax rate on uplift | B19: 0.25
A20: Uplift depreciation life (years) | B20: 15
A21: BP at close, 31 Dec 2026 (Python standalone forecast)
A22: Equity attributable to shareholders | B22: 51768.904
A23: Goodwill | B23: 10300
A24: Fixed assets | B24: 105335.1
A25: Borrowings + revolver | B25: 57958
A26: Lease liabilities | B26: 14571
A27: Cash | B27: 36684.504
A28: Minorities (incl. hybrids) | B28: 20948
A29: EBITDA 2026 | B29: 36655.089
A31: Consideration, funding and ownership
A32: BP market capitalisation | B32: =$B$8*$B$7/100*$B$9 -> 120016.47
A33: Equity purchase price | B33: =B32*(1+$B$11) -> 156021.41
A34: Offer per BP share (GBp) | B34: =$B$7*(1+$B$11) -> 764.4
A35: Paid in new Shell shares | B35: =B33*$B$12 -> 78010.703
A36: Paid in cash | B36: =B33-B35 -> 78010.703
A37: New Shell shares issued (m) | B37: =B35/($B$5/100*$B$9) -> 1539.7149
A38: Pro forma shares (m) | B38: =$B$6+B37 -> 7231.1896
A39: BP holders' ownership | B39: =B37/B38 -> 0.21292692
A40: BP net debt incl. leases | B40: =$B$25+$B$26-$B$27 -> 35844.496
A41: Target enterprise value (price + net debt + minorities) | B41: =B33+B40+$B$28 -> 212813.9
A42: Advisory fees | B42: =$B$13*B41 -> 638.4417
...

Sheet Portfolio
A1: Portfolio · 13 assets in GBP
A2: Annualised, from weekly GBP returns since Jan 2021 (Yahoo Finance adjusted closes). Covariance is Ledoit-Wolf shrunk. Weights come from the Python optimiser (it cannot be expressed as formulas); edit any weight and the statistics recalculate.
A4: Inputs
A5: Risk-free rate | B5: 0.040500002
A6: Equity risk premium (CAPM prior) | B6: 0.05
A7: Weight on history in expected returns | B7: 0.25
A9: Asset | B9: Hist. mean | C9: Beta | D9: Exp. return | E9: Max Sharpe | F9: Min variance | G9: Risk parity | H9: Max diversification | I9: Equal weight
A10: Barclays | B10: 0.22788475 | C10: 1.573361 | D10: =$B$7*B10+(1-$B$7)*($B$5+C10*$B$6) -> 0.14634723 | E10: 0.082172572 | F10: 0.0062407812 | G10: 0.056399564 | H10: 0.015734505 | I10: 0.076923077
A11: Prudential | B11: -0.028946613 | C11: 1.4358786 | D11: =$B$7*B11+(1-$B$7)*($B$5+C11*$B$6) -> 0.076983796 | E11: 0 | F11: 0 | G11: 0.05434188 | H11: 0.019923888 | I11: 0.076923077
A12: Rolls-Royce | B12: 0.51335462 | C12: 1.2617923 | D12: =$B$7*B12+(1-$B$7)*($B$5+C12*$B$6) -> 0.20603087 | E12: 0.21010406 | F12: 0.045896112 | G12: 0.059600768 | H12: 0.088908062 | I12: 0.076923077
A13: Glencore | B13: 0.18269406 | C13: 1.331847 | D13: =$B$7*B13+(1-$B$7)*($B$5+C13*$B$6) -> 0.12599278 | E13: 0.10695193 | F13: 0.062253066 | G13: 0.066878034 | H13: 0.10171685 | I13: 0.076923077
A14: SSE | B14: 0.10298106 | C14: 0.77479947 | D14: =$B$7*B14+(1-$B$7)*($B$5+C14*$B$6) -> 0.085175246 | E14: 0.035828815 | F14: 0.031144737 | G14: 0.07640227 | H14: 0.045927863 | I14: 0.076923077
A15: United Utilities | B15: 0.09487951 | C15: 0.52892053 | D15: =$B$7*B15+(1-$B$7)*($B$5+C15*$B$6) -> 0.073929399 | E15: 0.077798111 | F15: 0.14458941 | G15: 0.095826396 | H15: 0.11215206 | I15: 0.076923077
A16: BT | B16: 0.10072851 | C16: 0.87416857 | D16: =$B$7*B16+(1-$B$7)*($B$5+C16*$B$6) -> 0.088338451 | E16: 1.8566109e-17 | F16: 0.014405352 | G16: 0.06261473 | H16: 0.059129019 | I16: 0.076923077
A17: British American Tobacco | B17: 0.095154607 | C17: 0.63700814 | D17: =$B$7*B17+(1-$B$7)*($B$5+C17*$B$6) -> 0.078051458 | E17: 0.069676987 | F17: 0.12277188 | G17: 0.10018535 | H17: 0.13259578 | I17: 0.076923077
A18: AstraZeneca | B18: 0.1098184 | C18: 0.94103547 | D18: =$B$7*B18+(1-$B$7)*($B$5+C18*$B$6) -> 0.093118431 | E18: 0.078390933 | F18: 0.070065984 | G18: 0.087346327 | H18: 0.090023417 | I18: 0.076923077
A19: Palantir | B19: 0.58290943 | C19: 0.63472303 | D19: =$B$7*B19+(1-$B$7)*($B$5+C19*$B$6) -> 0.19990447 | E19: 0.072580529 | F19: 0.016887751 | G19: 0.043187958 | H19: 0.072163415 | I19: 0.076923077
A20: Coca-Cola | B20: 0.14358825 | C20: 0.42019088 | D20: =$B$7*B20+(1-$B$7)*($B$5+C20*$B$6) -> 0.082029222 | E20: 0.25 | F20: 0.24871097 | G20: 0.12998784 | H20: 0.1748181 | I20: 0.076923077
A21: Equinix | B21: 0.12456443 | C21: 0.47375468 | D21: =$B$7*B21+(1-$B$7)*($B$5+C21*$B$6) -> 0.079281909 | E21: 0.016496064 | F21: 0.059598054 | G21: 0.079990739 | H21: 0.077736274 | I21: 0.076923077
A22: EEMA | B22: 0.073548998 | C22: 0.68936491 | D22: =$B$7*B22+(1-$B$7)*($B$5+C22*$B$6) -> 0.074613435 | E22: 2.5033862e-17 | F22: 0.17743591 | G22: 0.087238139 | H22: 0.0091707707 | I22: 0.076923077
A23: Sum of weights | E23: =SUM(E10:E22) -> 1 | F23: =SUM(F10:F22) -> 1 | G23: =SUM(G10:G22) -> 1 | H23: =SUM(H10:H22) -> 1 | I23: =SUM(I10:I22) -> 1
A25: Annual covariance matrix (Ledoit-Wolf)
B26: Barclays | C26: Prudential | D26: Rolls-Royce | E26: Glencore | F26: SSE | G26: United Utilities | H26: BT | I26: British American Tobacco | J26: AstraZeneca | K26: Palantir | L26: Coca-Cola | M26: Equinix | N26: EEMA
A27: Barclays | B27: 0.090884375 | C27: 0.041341857 | D27: 0.042273441 | E27: 0.028933813 | F27: 0.0086916697 | G27: 0.003917644 | H27: 0.016942914 | I27: 0.01040297 | J27: 0.0054881265 | K27: 0.023749145 | L27: 0.0020746216 | M27: 0.0064490699 | N27: 0.019002771
A28: Prudential | B28: 0.041341857 | C28: 0.090557435 | D28: 0.031934093 | E28: 0.033199627 | F28: 0.010369645 | G28: 0.0093611827 | H28: 0.023441673 | I28: 0.0067482221 | J28: 0.0068170346 | K28: 0.011307217 | L28: 0.003976102 | M28: 0.0071232468 | N28: 0.025841037
A29: Rolls-Royce | B29: 0.042273441 | C29: 0.031934093 | D29: 0.13823808 | E29: 0.018527042 | F29: 0.002759167 | G29: 0.00075906317 | H29: 0.016994579 | I29: -0.00044808444 | J29: 0.010201913 | K29: 0.023928598 | L29: -0.0012793075 | M29: -0.0024089227 | N29: 0.016458597
A30: Glencore | B30: 0.028933813 | C30: 0.033199627 | D30: 0.018527042 | E30: 0.10362511 | F30: 0.0109657 | G30: 0.00061274349 | H30: 0.0070008773 | I30: 0.00026681621 | J30: 0.0087171512 | K30: 0.013023005 | L30: -0.0021030594 | M30: 0.0081636368 | N30: 0.01625788
A31: SSE | B31: 0.0086916697 | C31: 0.010369645 | D31: 0.002759167 | E31: 0.0109657 | F31: 0.059398243 | G31: 0.023266328 | H31: 0.015667271 | I31: 0.0084047919 | J31: 0.015216712 | K31: -0.0088823823 | L31: 0.0089159525 | M31: 0.013825272 | N31: 0.0024352353
A32: United Utilities | B32: 0.003917644 | C32: 0.0093611827 | D32: 0.00075906317 | E32: 0.00061274349 | F32: 0.023266328 | G32: 0.044159698 | H32: 0.018005553 | I32: 0.0062652581 | J32: 0.0093654865 | K32: -0.0061143065 | L32: 0.0071807884 | M32: 0.0098883277 | N32: 0.0031606047
A33: BT | B33: 0.016942914 | C33: 0.023441673 | D33: 0.016994579 | E33: 0.0070008773 | F33: 0.015667271 | G33: 0.018005553 | H33: 0.097051292 | I33: 0.016576418 | J33: 0.0080292609 | K33: 0.0018677834 | L33: 0.005806476 | M33: 0.0044981637 | N33: 0.0088613001
A34: British American Tobacco | B34: 0.01040297 | C34: 0.0067482221 | D34: -0.00044808444 | E34: 0.00026681621 | F34: 0.0084047919 | G34: 0.0062652581 | H34: 0.016576418 | I34: 0.052292317 | J34: 0.0098647504 | K34: -0.0097500065 | L34: 0.012486869 | M34: 0.00042112319 | N34: 0.0010150448
A35: AstraZeneca | B35: 0.0054881265 | C35: 0.0068170346 | D35: 0.010201913 | E35: 0.0087171512 | F35: 0.015216712 | G35: 0.0093654865 | H35: 0.0080292609 | I35: 0.0098647504 | J35: 0.057325872 | K35: -0.011455994 | L35: 0.0099294876 | M35: 0.007582757 | N35: 0.004395997
A36: Palantir | B36: 0.023749145 | C36: 0.011307217 | D36: 0.023928598 | E36: 0.013023005 | F36: -0.0088823823 | G36: -0.0061143065 | H36: 0.0018677834 | I36: -0.0097500065 | J36: -0.011455994 | K36: 0.43631594 | L36: -0.011702028 | M36: 0.042508707 | N36: 0.032742027
A37: Coca-Cola | B37: 0.0020746216 | C37: 0.003976102 | D37: -0.0012793075 | E37: -0.0021030594 | F37: 0.0089159525 | G37: 0.0071807884 | H37: 0.005806476 | I37: 0.012486869 | J37: 0.0099294876 | K37: -0.011702028 | L37: 0.029939542 | M37: 0.0069200559 | N37: 0.0034489641
A38: Equinix | B38: 0.0064490699 | C38: 0.0071232468 | D38: -0.0024089227 | E38: 0.0081636368 | F38: 0.013825272 | G38: 0.0098883277 | H38: 0.0044981637 | I38: 0.00042112319 | J38: 0.007582757 | K38: 0.042508707 | L38: 0.0069200559 | M38: 0.065952258 | N38: 0.013576664
A39: EEMA | B39: 0.019002771 | C39: 0.025841037 | D39: 0.016458597 | E39: 0.01625788 | F39: 0.0024352353 | G39: 0.0031606047 | H39: 0.0088613001 | I39: 0.0010150448 | J39: 0.004395997 | K39: 0.032742027 | L39: 0.0034489641 | M39: 0.013576664 | N39: 0.036777427
A41: Weights as rows (for w′Σw)
A42: Max Sharpe | B42: =E10 -> 0.082172572 | C42: =E11 -> 0 | D42: =E12 -> 0.21010406 | E42: =E13 -> 0.10695193 | F42: =E14 -> 0.035828815 | G42: =E15 -> 0.077798111 | H42: =E16 -> 1.8566109e-17 | I42: =E17 -> 0.069676987 | J42: =E18 -> 0.078390933 | K42: =E19 -> 0.072580529 | L42: =E20 -> 0.25 | M42: =E21 -> 0.016496064 | N42: =E22 -> 2.5033862e-17
A43: Min variance | B43: =F10 -> 0.0062407812 | C43: =F11 -> 0 | D43: =F12 -> 0.045896112 | E43: =F13 -> 0.062253066 | F43: =F14 -> 0.031144737 | G43: =F15 -> 0.14458941 | H43: =F16 -> 0.014405352 | I43: =F17 -> 0.12277188 | J43: =F18 -> 0.070065984 | K43: =F19 -> 0.016887751 | L43: =F20 -> 0.24871097 | M43: =F21 -> 0.059598054 | N43: =F22 -> 0.17743591
A44: Risk parity | B44: =G10 -> 0.056399564 | C44: =G11 -> 0.05434188 | D44: =G12 -> 0.059600768 | E44: =G13 -> 0.066878034 | F44: =G14 -> 0.07640227 | G44: =G15 -> 0.095826396 | H44: =G16 -> 0.06261473 | I44: =G17 -> 0.10018535 | J44: =G18 -> 0.087346327 | K44: =G19 -> 0.043187958 | L44: =G20 -> 0.12998784 | M44: =G21 -> 0.079990739 | N44: =G22 -> 0.087238139
...

Sheet Checks
A1: Checks · workbook vs Python engine
A2: Each line compares a live Excel result with the Python engine. Tolerances are absolute.
A4: Check | B4: Excel | C4: Python | D4: Difference | E4: Tolerance | F4: Status
A5: History balances (max abs, FY2021–25) | B5: =MAX(ABS(History!B46),ABS(History!C46),ABS(History!D46),ABS(History!E46),ABS(History!F46)) -> 0 | C5: 0 | D5: =B5-C5 -> 0 | E5: 0.5 | F5: =IFERROR(IF(ABS(D5)<=E5,"PASS","FAIL"),"ERROR") -> PASS
A6: Forecast balance sheet balances (max abs) | B6: =MAX(Forecast!B54:'Forecast'!L54,-MIN(Forecast!B54:'Forecast'!L54)) -> 0 | C6: 0 | D6: =B6-C6 -> 0 | E6: 0.01 | F6: =IFERROR(IF(ABS(D6)<=E6,"PASS","FAIL"),"ERROR") -> PASS
A7: Revenue 2035 | B7: =Forecast!L6 -> 308095.63 | C7: 308095.63 | D7: =B7-C7 -> 0 | E7: 0.01 | F7: =IFERROR(IF(ABS(D7)<=E7,"PASS","FAIL"),"ERROR") -> PASS
A8: Net income 2026 | B8: =Forecast!C15 -> 17911.643 | C8: 17911.643 | D8: =B8-C8 -> 0 | E8: 0.01 | F8: =IFERROR(IF(ABS(D8)<=E8,"PASS","FAIL"),"ERROR") -> PASS
A9: Closing cash 2030 | B9: =Forecast!G41 -> 25487.391 | C9: 25487.391 | D9: =B9-C9 -> 0 | E9: 0.01 | F9: =IFERROR(IF(ABS(D9)<=E9,"PASS","FAIL"),"ERROR") -> PASS
A10: Buybacks 2028 | B10: =Forecast!E35 -> 5849.5696 | C10: 5849.5696 | D10: =B10-C10 -> -1.4551915e-11 | E10: 0.01 | F10: =IFERROR(IF(ABS(D10)<=E10,"PASS","FAIL"),"ERROR") -> PASS
A11: Unlevered FCF 2035 | B11: =Forecast!L57 -> 19076.616 | C11: 19076.616 | D11: =B11-C11 -> 0 | E11: 0.01 | F11: =IFERROR(IF(ABS(D11)<=E11,"PASS","FAIL"),"ERROR") -> PASS
A12: WACC | B12: =DCF!B9 -> 0.082461588 | C12: 0.082461588 | D12: =B12-C12 -> 0 | E12: 1e-09 | F12: =IFERROR(IF(ABS(D12)<=E12,"PASS","FAIL"),"ERROR") -> PASS
A13: Enterprise value | B13: =DCF!B22 -> 253060.71 | C13: 253060.71 | D13: =B13-C13 -> 0 | E13: 0.05 | F13: =IFERROR(IF(ABS(D13)<=E13,"PASS","FAIL"),"ERROR") -> PASS
A14: Equity value | B14: =DCF!B30 -> 189884.96 | C14: 189884.96 | D14: =B14-C14 -> 0 | E14: 0.05 | F14: =IFERROR(IF(ABS(D14)<=E14,"PASS","FAIL"),"ERROR") -> PASS
A15: DCF value per share (pence) | B15: =DCF!B34 -> 2621.1419 | C15: 2621.1419 | D15: =B15-C15 -> 0 | E15: 0.01 | F15: =IFERROR(IF(ABS(D15)<=E15,"PASS","FAIL"),"ERROR") -> PASS
A16: Exit-multiple value per share (pence) | B16: =DCF!B43 -> 2607.1469 | C16: 2607.1469 | D16: =B16-C16 -> 0 | E16: 0.01 | F16: =IFERROR(IF(ABS(D16)<=E16,"PASS","FAIL"),"ERROR") -> PASS
A17: Sensitivity grid centre = point estimate | B17: =DCF!D49 -> 2621.1419 | C17: 2621.1419 | D17: =B17-C17 -> 0 | E17: 0.01 | F17: =IFERROR(IF(ABS(D17)<=E17,"PASS","FAIL"),"ERROR") -> PASS
A18: Interest expense 2027 | B18: =Forecast!D10 -> 4671 | C18: 4671 | D18: =B18-C18 -> 0 | E18: 0.01 | F18: =IFERROR(IF(ABS(D18)<=E18,"PASS","FAIL"),"ERROR") -> PASS
A19: Shareholders' equity 2035 | B19: =Forecast!L51 -> 195159.27 | C19: 195159.27 | D19: =B19-C19 -> 0 | E19: 0.01 | F19: =IFERROR(IF(ABS(D19)<=E19,"PASS","FAIL"),"ERROR") -> PASS
A20: LBO sponsor equity | B20: =LBO!B55 -> 25413.051 | C20: 25413.051 | D20: =B20-C20 -> 0 | E20: 0.01 | F20: =IFERROR(IF(ABS(D20)<=E20,"PASS","FAIL"),"ERROR") -> PASS
A21: LBO cash interest, year 1 | B21: =LBO!C75 -> 2721.8918 | C21: 2721.8918 | D21: =B21-C21 -> -3.1923264e-10 | E21: 0.01 | F21: =IFERROR(IF(ABS(D21)<=E21,"PASS","FAIL"),"ERROR") -> PASS
A22: LBO term loan B after year 5 | B22: =LBO!G87 -> 9976.8266 | C22: 9976.8266 | D22: =B22-C22 -> -2.5975169e-09 | E22: 0.01 | F22: =IFERROR(IF(ABS(D22)<=E22,"PASS","FAIL"),"ERROR") -> PASS
A23: LBO IRR | B23: =LBO!B103 -> 0.065795311 | C23: 0.065795311 | D23: =B23-C23 -> 1.5987212e-14 | E23: 1e-06 | F23: =IFERROR(IF(ABS(D23)<=E23,"PASS","FAIL"),"ERROR") -> PASS
A24: LBO MOIC | B24: =LBO!B102 -> 1.37521 | C24: 1.37521 | D24: =B24-C24 -> 1.0236256e-13 | E24: 1e-06 | F24: =IFERROR(IF(ABS(D24)<=E24,"PASS","FAIL"),"ERROR") -> PASS
A25: Merger: equity purchase price | B25: =Merger!B33 -> 156021.41 | C25: 156021.41 | D25: =B25-C25 -> 0 | E25: 0.01 | F25: =IFERROR(IF(ABS(D25)<=E25,"PASS","FAIL"),"ERROR") -> PASS
A26: Merger: acquisition debt | B26: =Merger!B44 -> 79443.58 | C26: 79443.58 | D26: =B26-C26 -> 0 | E26: 0.01 | F26: =IFERROR(IF(ABS(D26)<=E26,"PASS","FAIL"),"ERROR") -> PASS
A27: Merger: BP holders' ownership | B27: =Merger!B39 -> 0.21292692 | C27: 0.21292692 | D27: =B27-C27 -> 0 | E27: 1e-09 | F27: =IFERROR(IF(ABS(D27)<=E27,"PASS","FAIL"),"ERROR") -> PASS
A28: Merger: goodwill created | B28: =Merger!B51 -> 108232.4 | C28: 108232.4 | D28: =B28-C28 -> 0 | E28: 0.01 | F28: =IFERROR(IF(ABS(D28)<=E28,"PASS","FAIL"),"ERROR") -> PASS
A29: Merger: EPS accretion 2029 | B29: =Merger!D60 -> 0.16823331 | C29: 0.16823331 | D29: =B29-C29 -> 0 | E29: 1e-06 | F29: =IFERROR(IF(ABS(D29)<=E29,"PASS","FAIL"),"ERROR") -> PASS
A30: Portfolio volatility · Max Sharpe | B30: =Portfolio!C50 -> 0.1382397 | C30: 0.1382397 | D30: =B30-C30 -> 0 | E30: 1e-08 | F30: =IFERROR(IF(ABS(D30)<=E30,"PASS","FAIL"),"ERROR") -> PASS
A31: Portfolio expected return · Max Sharpe | B31: =Portfolio!B50 -> 0.12665446 | C31: 0.12665446 | D31: =B31-C31 -> 0 | E31: 1e-08 | F31: =IFERROR(IF(ABS(D31)<=E31,"PASS","FAIL"),"ERROR") -> PASS
A32: Portfolio volatility · Min variance | B32: =Portfolio!C51 -> 0.10828065 | C32: 0.10828065 | D32: =B32-C32 -> 0 | E32: 1e-08 | F32: =IFERROR(IF(ABS(D32)<=E32,"PASS","FAIL"),"ERROR") -> PASS
A33: Portfolio expected return · Min variance | B33: =Portfolio!B51 -> 0.090676102 | C33: 0.090676102 | D33: =B33-C33 -> 0 | E33: 1e-08 | F33: =IFERROR(IF(ABS(D33)<=E33,"PASS","FAIL"),"ERROR") -> PASS
A34: Portfolio volatility · Risk parity | B34: =Portfolio!C52 -> 0.11777317 | C34: 0.11777317 | D34: =B34-C34 -> 0 | E34: 1e-08 | F34: =IFERROR(IF(ABS(D34)<=E34,"PASS","FAIL"),"ERROR") -> PASS
A35: Portfolio expected return · Risk parity | B35: =Portfolio!B52 -> 0.10036676 | C35: 0.10036676 | D35: =B35-C35 -> 0 | E35: 1e-08 | F35: =IFERROR(IF(ABS(D35)<=E35,"PASS","FAIL"),"ERROR") -> PASS
A36: Portfolio volatility · Max diversification | B36: =Portfolio!C53 -> 0.11994171 | C36: 0.11994171 | D36: =B36-C36 -> 0 | E36: 1e-08 | F36: =IFERROR(IF(ABS(D36)<=E36,"PASS","FAIL"),"ERROR") -> PASS
A37: Portfolio expected return · Max diversification | B37: =Portfolio!B53 -> 0.10674199 | C37: 0.10674199 | D37: =B37-C37 -> 0 | E37: 1e-08 | F37: =IFERROR(IF(ABS(D37)<=E37,"PASS","FAIL"),"ERROR") -> PASS
A38: Portfolio volatility · Equal weight | B38: =Portfolio!C54 -> 0.13159324 | C38: 0.13159324 | D38: =B38-C38 -> 0 | E38: 1e-08 | F38: =IFERROR(IF(ABS(D38)<=E38,"PASS","FAIL"),"ERROR") -> PASS
A39: Portfolio expected return · Equal weight | B39: =Portfolio!B54 -> 0.1084459 | C39: 0.1084459 | D39: =B39-C39 -> 0 | E39: 1e-08 | F39: =IFERROR(IF(ABS(D39)<=E39,"PASS","FAIL"),"ERROR") -> PASS
A40: Portfolio weights sum to 100% (max abs error) | B40: =MAX(ABS(Portfolio!E23-1),ABS(Portfolio!F23-1),ABS(Portfolio!G23-1),ABS(Portfolio!H23-1),ABS(Portfolio!I23-1)) -> 2.220446e-16 | C40: 0 | D40: =B40-C40 -> 2.220446e-16 | E40: 1e-06 | F40: =IFERROR(IF(ABS(D40)<=E40,"PASS","FAIL"),"ERROR") -> PASS
A42: Overall | F42: =IF(COUNTIF(F5:F40,"PASS")=ROWS(F5:F40),"ALL PASS",ROWS(F5:F40)-COUNTIF(F5:F40,"PASS")&" NOT PASSING") -> ALL PASS

Sheet History
A1: Shell plc · reported history
A2: USD millions. Source: Shell plc Form 20-F, FY2021–FY2025, XBRL facts via SEC EDGAR (https://data.sec.gov/api/xbrl/companyfacts/CIK0001306965.json). Derived lines are noted.
A4: Line item (USD m) | B4: 2021 | C4: 2022 | D4: 2023 | E4: 2024 | F4: 2025
A5: Revenue | B5: 261504 | C5: 381314 | D5: 316620 | E5: 284312 | F5: 266886
A6: Profit before tax | B6: 29829 | C6: 64815 | D6: 32627 | E6: 29922 | F6: 29756
A7: Taxation | B7: 9199 | C7: 21941 | D7: 12991 | E7: 13401 | F7: 11637
A8: Net income | B8: 20630 | C8: 42874 | D8: 19636 | E8: 16521 | F8: 18119
A9: Net income to shareholders | B9: 20101 | C9: 42309 | D9: 19359 | E9: 16094 | F9: 17837
A10: D&A incl. impairments (cash-flow add-back) | B10: 26921 | C10: 18529 | D10: 31290 | E10: 26872 | F10: 25299
A11: Interest expense | B11: 3607 | C11: 3181 | D11: 4673 | E11: 4787 | F11: 4671
A12: Cash from operations | B12: 45104 | C12: 68414 | D12: 54191 | E12: 54687 | F12: 42863
A13: Cash from investing | B13: -4761 | C13: -22448 | D13: -17734 | E13: -15155 | F13: -16811
A14: Cash from financing | B14: -34664 | C14: -41954 | D14: -38235 | E14: -38435 | F14: -35812
A15: Capital expenditure | B15: 19000 | C15: 22600 | D15: 22993 | E15: 19601 | F15: 18947
A16: Dividends paid | B16: 6669 | C16: 7489 | D16: 9153 | E16: 8976 | F16: 8619
... A44: Operating EBIT, ex JV and finance items (derived) | B44: 22283 | C44: 63109 | D44: 30737 | E44: 29992 | F44: 27582
A46: Balance check: total assets − total liabilities − total equity | B46: =B18-B26-B32 -> 0 | C46: =C18-C26-C32 -> 0 | D46: =D18-D26-D32 -> 0 | E46: =E18-E26-E32 -> 0 | F46: =F18-F26-F32 -> 0
